<?xml version="1.0"?>
<robot name="flexible_arm">
    <material name = "custom">
        <color rgba = "0.596 0.564 0.572 1"/>
    </material>

    <!-- world -->
    <link name="world"/>

  <!-- flexible arm modeled using virtual link method -->
    <link name="rfe_1">
         <visual>
            <geometry>
                <cylinder radius="0.003" length="0.06" />
            </geometry>
            <origin rpy="0 1.57075 0" xyz ="0.03 0 0"/>
            <material name = "custom"/>
        </visual>
        <inertial>
            <origin xyz="0.03 0 0" rpy="0 0 0"/>
            <mass value="0.004597406689263303" />
            <inertia ixx="2.06883301e-08" ixy="0" ixz="0" iyy="1.38956617e-06" iyz="0" izz="1.38956617e-06" />
        </inertial>
    </link>

    <joint name="active_joint" type="revolute">
        <parent link="world"/>
        <child link="rfe_1"/>
        <axis xyz="0 0 1"/>
        <origin xyz="0 0 0.5" rpy="1.57 0 0"/>
        <limit effort="100.0" lower="-3.14159" upper="3.14159" velocity="3.14"/>
    </joint>

    <link name="rfe_2">
        <visual>
            <geometry>
                <cylinder radius="0.003" length="0.12" />
            </geometry>
            <origin rpy="0 1.57075 0" xyz ="0.06 0 0"/>
            <material name = "custom"/>
        </visual>
        <inertial>
            <origin xyz="0.06 0 0" rpy="0 0 0"/>
            <mass value="0.009194813378526605" />
            <inertia ixx="4.13766602e-08" ixy="0" ixz="0" iyy="1.10544644e-05" iyz="0" izz="1.10544644e-05" />
        </inertial>
    </link>

    <joint name="sde_joint_1" type="revolute">
        <parent link="rfe_1"/>
        <child link="rfe_2"/>
        <axis xyz="0 0 1"/>
        <origin xyz="0.06 0 0" rpy="0 0 0"/>
        <limit effort="100.0" lower="-3.14159" upper="3.14159" velocity="3.14"/>
    </joint>

    <link name="rfe_3">
        <visual>
            <geometry>
                <cylinder radius="0.003" length="0.12" />
            </geometry>
            <origin rpy="0 1.57075 0" xyz ="0.06 0 0"/>
            <material name = "custom"/>
        </visual>
        <inertial>
            <origin xyz="0.06 0 0" rpy="0 0 0"/>
            <mass value="0.009194813378526605" />
            <inertia ixx="4.13766602e-08" ixy="0" ixz="0" iyy="1.10544644e-05" iyz="0" izz="1.10544644e-05" />
        </inertial>
    </link>

    <joint name="sde_joint_2" type="revolute">
        <parent link="rfe_2"/>
        <child link="rfe_3"/>
        <axis xyz="0 0 1"/>
        <origin xyz="0.12 0 0" rpy="0 0 0"/>
        <limit effort="100.0" lower="-3.14159" upper="3.14159" velocity="3.14"/>
    </joint>

    <link name="rfe_4">
        <visual>
            <geometry>
                <cylinder radius="0.003" length="0.12" />
            </geometry>
            <origin rpy="0 1.57075 0" xyz ="0.06 0 0"/>
            <material name = "custom"/>
        </visual>
        <inertial>
            <origin xyz="0.06 0 0" rpy="0 0 0"/>
            <mass value="0.009194813378526605" />
            <inertia ixx="4.13766602e-08" ixy="0" ixz="0" iyy="1.10544644e-05" iyz="0" izz="1.10544644e-05" />
        </inertial>
    </link>

    <joint name="sde_joint_3" type="revolute">
        <parent link="rfe_3"/>
        <child link="rfe_4"/>
        <axis xyz="0 0 1"/>
        <origin xyz="0.12 0 0" rpy="0 0 0"/>
        <limit effort="100.0" lower="-3.14159" upper="3.14159" velocity="3.14"/>
    </joint>

    <link name="rfe_5">
        <visual>
            <geometry>
                <cylinder radius="0.003" length="0.12" />
            </geometry>
            <origin rpy="0 1.57075 0" xyz ="0.06 0 0"/>
            <material name = "custom"/>
        </visual>
        <inertial>
            <origin xyz="0.06 0 0" rpy="0 0 0"/>
            <mass value="0.009194813378526605" />
            <inertia ixx="4.13766602e-08" ixy="0" ixz="0" iyy="1.10544644e-05" iyz="0" izz="1.10544644e-05" />
        </inertial>
    </link>

    <joint name="sde_joint_4" type="revolute">
        <parent link="rfe_4"/>
        <child link="rfe_5"/>
        <axis xyz="0 0 1"/>
        <origin xyz="0.12 0 0" rpy="0 0 0"/>
        <limit effort="100.0" lower="-3.14159" upper="3.14159" velocity="3.14"/>
    </joint>

    <link name="rfe_6">
        <visual>
            <geometry>
                <cylinder radius="0.003" length="0.12" />
            </geometry>
            <origin rpy="0 1.57075 0" xyz ="0.06 0 0"/>
            <material name = "custom"/>
        </visual>
        <inertial>
            <origin xyz="0.06 0 0" rpy="0 0 0"/>
            <mass value="0.009194813378526605" />
            <inertia ixx="4.13766602e-08" ixy="0" ixz="0" iyy="1.10544644e-05" iyz="0" izz="1.10544644e-05" />
        </inertial>
    </link>

    <joint name="sde_joint_5" type="revolute">
        <parent link="rfe_5"/>
        <child link="rfe_6"/>
        <axis xyz="0 0 1"/>
        <origin xyz="0.12 0 0" rpy="0 0 0"/>
        <limit effort="100.0" lower="-3.14159" upper="3.14159" velocity="3.14"/>
    </joint>

    <link name="rfe_7">
        <visual>
            <geometry>
                <cylinder radius="0.003" length="0.12" />
            </geometry>
            <origin rpy="0 1.57075 0" xyz ="0.06 0 0"/>
            <material name = "custom"/>
        </visual>
        <inertial>
            <origin xyz="0.06 0 0" rpy="0 0 0"/>
            <mass value="0.009194813378526605" />
            <inertia ixx="4.13766602e-08" ixy="0" ixz="0" iyy="1.10544644e-05" iyz="0" izz="1.10544644e-05" />
        </inertial>
    </link>

    <joint name="sde_joint_6" type="revolute">
        <parent link="rfe_6"/>
        <child link="rfe_7"/>
        <axis xyz="0 0 1"/>passive_joint
        <origin xyz="0.12 0 0" rpy="0 0 0"/>
        <limit effort="100.0" lower="-3.14159" upper="3.14159" velocity="3.14"/>
    </joint>

    <link name="rfe_8">
        <visual>
            <geometry>
                <cylinder radius="0.003" length="0.12" />
            </geometry>
            <origin rpy="0 1.57075 0" xyz ="0.06 0 0"/>
            <material name = "custom"/>
        </visual>
        <inertial>
            <origin xyz="0.06 0 0" rpy="0 0 0"/>
            <mass value="0.009194813378526605" />
            <inertia ixx="4.13766602e-08" ixy="0" ixz="0" iyy="1.10544644e-05" iyz="0" izz="1.10544644e-05" />
        </inertial>
    </link>

    <joint name="sde_joint_7" type="revolute">
        <parent link="rfe_7"/>
        <child link="rfe_8"/>
        <axis xyz="0 0 1"/>
        <origin xyz="0.12 0 0" rpy="0 0 0"/>
        <limit effort="100.0" lower="-3.14159" upper="3.14159" velocity="3.14"/>
    </joint>

    <link name="rfe_9">
        <visual>
            <geometry>
                <cylinder radius="0.003" length="0.12" />
            </geometry>
            <origin rpy="0 1.57075 0" xyz ="0.06 0 0"/>
            <material name = "custom"/>
        </visual>
        <inertial>
            <origin xyz="0.06 0 0" rpy="0 0 0"/>
            <mass value="0.009194813378526605" />
            <inertia ixx="4.13766602e-08" ixy="0" ixz="0" iyy="1.10544644e-05" iyz="0" izz="1.10544644e-05" />
        </inertial>
    </link>

    <joint name="sde_joint_8" type="revolute">
        <parent link="rfe_8"/>
        <child link="rfe_9"/>
        <axis xyz="0 0 1"/>
        <origin xyz="0.12 0 0" rpy="0 0 0"/>
        <limit effort="100.0" lower="-3.14159" upper="3.14159" velocity="3.14"/>
    </joint>

    <link name="rfe_10">
        <visual>
            <geometry>
                <cylinder radius="0.003" length="0.12" />
            </geometry>
            <origin rpy="0 1.57075 0" xyz ="0.06 0 0"/>
            <material name = "custom"/>
        </visual>
        <inertial>
            <origin xyz="0.06 0 0" rpy="0 0 0"/>
            <mass value="0.009194813378526605" />
            <inertia ixx="4.13766602e-08" ixy="0" ixz="0" iyy="1.10544644e-05" iyz="0" izz="1.10544644e-05" />
        </inertial>
    </link>

    <joint name="sde_joint_9" type="revolute">
        <parent link="rfe_9"/>
        <child link="rfe_10"/>
        <axis xyz="0 0 1"/>
        <origin xyz="0.12 0 0" rpy="0 0 0"/>
        <limit effort="100.0" lower="-3.14159" upper="3.14159" velocity="3.14"/>
    </joint>

    <link name="rfe_11">
         <visual>
            <geometry>
                <cylinder radius="0.003" length="0.06" />
            </geometry>
            <origin rpy="0 1.57075 0" xyz ="0.03 0 0"/>
            <material name = "custom"/>
        </visual>
        <inertial>
            <origin xyz="0.03 0 0" rpy="0 0 0"/>
            <mass value="0.004597406689263303" />
            <inertia ixx="2.06883301e-08" ixy="0" ixz="0" iyy="1.38956617e-06" iyz="0" izz="1.38956617e-06" />
        </inertial>
    </link>

    <joint name="sde_joint_10" type="revolute">
        <parent link="rfe_10"/>
        <child link="rfe_11"/>
        <axis xyz="0 0 1"/>
        <origin xyz="0.12 0 0" rpy="0 0 0"/>
        <limit effort="100.0" lower="-3.14159" upper="3.14159" velocity="3.14"/>
    </joint>

    <link name="load">
        <visual>
            <geometry>
                <sphere radius="0.02"/>
            </geometry>
            <origin rpy="0 0 0" xyz ="0.01 0 0"/>
            <material name = "custom"/>
        </visual>
        <inertial>
            <origin xyz="0.01 0 0" rpy="0 0 0"/>
            <mass value="0.00" />
            <inertia ixx="0" ixy="0" ixz="0" iyy="0" iyz="0" izz="0" />
        </inertial>
    </link>

    <joint name="rfe_11_to_load" type="fixed">
        <parent link="rfe_11"/>
        <child link="load"/>
        <axis xyz="0 0 1"/>
        <origin xyz="0.06 0 0" rpy="0 0 0"/>
    </joint>

</robot>
