<?xml version="1.0"?>
<robot name="flexible_arm">
    <material name = "custom">
        <color rgba = "0.596 0.564 0.572 1"/>
    </material>
    
    <!-- world -->
    <link name="world"/>

    <!-- flexible arm modeled using virtual link method -->
    <link name="rfe_1">
        <visual>
            <geometry>
                <cylinder radius="0.003" length="0.12" />
            </geometry>
            <origin rpy="0 1.57075 0" xyz ="0.06 0 0"/>
            <material name = "custom"/>
        </visual>
        <inertial>
            <origin xyz="0.06 0 0" rpy="0 0 0"/>
            <mass value="0.009194813378526605" />
            <inertia ixx="4.13766602e-08" ixy="0" ixz="0" iyy="1.10544644e-05" iyz="0" izz="1.10544644e-05" />
        </inertial>
    </link>

    <joint name="active_joint" type="revolute">
        <parent link="world"/>
        <child link="rfe_1"/>
        <axis xyz="0 0 1"/>
        <origin xyz="0 0 0.5" rpy="1.57 0 0"/>
        <limit effort="100.0" lower="-3.14159" upper="3.14159" velocity="3.14"/>
    </joint>

    <link name="rfe_2">
        <visual>
            <geometry>
                <cylinder radius="0.003" length="0.24" />
            </geometry>
            <origin rpy="0 1.57075 0" xyz ="0.12 0 0"/>
            <material name = "custom"/>
        </visual>
        <inertial>
            <origin xyz="0.12 0 0" rpy="0 0 0"/>
            <mass value="0.01838962675705321" />
            <inertia ixx="8.27533204e-08" ixy="0" ixz="0" iyy="8.83115851e-05" iyz="0" izz="8.83115851e-05" />
        </inertial>
    </link>

    <joint name="sde_joint_1" type="revolute">
        <parent link="rfe_1"/>
        <child link="rfe_2"/>
        <axis xyz="0 0 1"/>
        <origin xyz="0.12 0 0" rpy="0 0 0"/>
        <limit effort="100.0" lower="-3.14159" upper="3.14159" velocity="3.14"/>
    </joint>

    <link name="rfe_3">
        <visual>
            <geometry>
                <cylinder radius="0.003" length="0.24" />
            </geometry>
            <origin rpy="0 1.57075 0" xyz ="0.12 0 0"/>
            <material name = "custom"/>
        </visual>
        <inertial>
            <origin xyz="0.12 0 0" rpy="0 0 0"/>
            <mass value="0.01838962675705321" />
            <inertia ixx="8.27533204e-08" ixy="0" ixz="0" iyy="8.83115851e-05" iyz="0" izz="8.83115851e-05" />
        </inertial>
    </link>

    <joint name="sde_joint_2" type="revolute">
        <parent link="rfe_2"/>
        <child link="rfe_3"/>
        <axis xyz="0 0 1"/>
        <origin xyz="0.24 0 0" rpy="0 0 0"/>
        <limit effort="100.0" lower="-3.14159" upper="3.14159" velocity="3.14"/>
    </joint>

    <link name="rfe_4">
        <visual>
            <geometry>
                <cylinder radius="0.003" length="0.24" />
            </geometry>
            <origin rpy="0 1.57075 0" xyz ="0.12 0 0"/>
            <material name = "custom"/>
        </visual>
        <inertial>
            <origin xyz="0.12 0 0" rpy="0 0 0"/>
            <mass value="0.01838962675705321" />
            <inertia ixx="8.27533204e-08" ixy="0" ixz="0" iyy="8.83115851e-05" iyz="0" izz="8.83115851e-05" />
        </inertial>
    </link>

    <joint name="sde_joint_3" type="revolute">
        <parent link="rfe_3"/>
        <child link="rfe_4"/>
        <axis xyz="0 0 1"/>
        <origin xyz="0.24 0 0" rpy="0 0 0"/>
        <limit effort="100.0" lower="-3.14159" upper="3.14159" velocity="3.14"/>
    </joint>

    <link name="rfe_5">
        <visual>
            <geometry>
                <cylinder radius="0.003" length="0.24" />
            </geometry>
            <origin rpy="0 1.57075 0" xyz ="0.12 0 0"/>
            <material name = "custom"/>
        </visual>
        <inertial>
            <origin xyz="0.12 0 0" rpy="0 0 0"/>
            <mass value="0.01838962675705321" />
            <inertia ixx="8.27533204e-08" ixy="0" ixz="0" iyy="8.83115851e-05" iyz="0" izz="8.83115851e-05" />
        </inertial>
    </link>

    <joint name="sde_joint_4" type="revolute">
        <parent link="rfe_4"/>
        <child link="rfe_5"/>
        <axis xyz="0 0 1"/>
        <origin xyz="0.24 0 0" rpy="0 0 0"/>
        <limit effort="100.0" lower="-3.14159" upper="3.14159" velocity="3.14"/>
    </joint>

    <link name="rfe_6">
        <visual>
            <geometry>
                <cylinder radius="0.003" length="0.12" />
            </geometry>
            <origin rpy="0 1.57075 0" xyz ="0.06 0 0"/>
            <material name = "custom"/>
        </visual>
        <inertial>
            <origin xyz="0.06 0 0" rpy="0 0 0"/>
            <mass value="0.009194813378526605" />
            <inertia ixx="4.13766602e-08" ixy="0" ixz="0" iyy="1.10544644e-05" iyz="0" izz="1.10544644e-05" />
        </inertial>
    </link>

    <joint name="sde_joint_5" type="revolute">
        <parent link="rfe_5"/>
        <child link="rfe_6"/>
        <axis xyz="0 0 1"/>
        <origin xyz="0.24 0 0" rpy="0 0 0"/>
        <limit effort="100.0" lower="-3.14159" upper="3.14159" velocity="3.14"/>
    </joint>

    <link name="load">
        <visual>
            <geometry>
                <sphere radius="0.02"/>
            </geometry>
            <origin rpy="0 0 0" xyz ="0.01 0 0"/>
            <material name = "custom"/>
        </visual>
        <inertial>
            <origin xyz="0.01 0 0" rpy="0 0 0"/>
            <mass value="0.00" />
            <inertia ixx="0" ixy="0" ixz="0" iyy="0" iyz="0" izz="0" />
        </inertial>
    </link>

    <joint name="rfe_6_to_load" type="fixed">
        <parent link="rfe_6"/>
        <child link="load"/>
        <axis xyz="0 0 1"/>
        <origin xyz="0.12 0 0" rpy="0 0 0"/>
    </joint>

</robot>
